2014/01/26 23:20:03 [error] 7536#0: *1 FastCGI sent in stderr: "" while reading response header from upstream, client: 192.168.56.1, server: , request: "GET / HTTP/1.1", upstream: "fastcgi://127.0.0.1:9000", host: "in.dev"
2014/01/26 23:20:03 [error] 7536#0: *1 FastCGI sent in stderr: "Traceback (most recent call last):
  File "/usr/local/lib/python2.7/dist-packages/flup/server/fcgi_base.py", line 574, in run
    protocolStatus, appStatus = self.server.handler(self)
  File "/usr/local/lib/python2.7/dist-packages/flup/server/fcgi_base.py", line 1159, in handler
    result = self.application(environ, start_response)
  File "/usr/local/lib/python2.7/dist-packages/django/core/handlers/wsgi.py", line 219, in __call__
    self.load_middleware()
  File "/usr/local/lib/python2.7/dist-packages/django/core/handlers/base.py", line 47, in load_middleware
    raise exceptions.ImproperlyConfigured('Error importing middleware %s: "%s"' % (mw_module, e))
ImproperlyConfigured: Error importing middleware hopeapp.middleware.crossdomainxhr: "No module named middleware.crossdomainxhr"" while reading response header from upstream, client: 192.168.56.1, server: , request: "GET / HTTP/1.1", upstream: "fastcgi://127.0.0.1:9000", host: "in.dev"
2014/01/26 23:20:05 [error] 7536#0: *1 FastCGI sent in stderr: "" while reading response header from upstream, client: 192.168.56.1, server: , request: "GET / HTTP/1.1", upstream: "fastcgi://127.0.0.1:9000", host: "in.dev"
2014/01/26 23:20:05 [error] 7536#0: *1 FastCGI sent in stderr: "Traceback (most recent call last):
  File "/usr/local/lib/python2.7/dist-packages/flup/server/fcgi_base.py", line 574, in run
    protocolStatus, appStatus = self.server.handler(self)
  File "/usr/local/lib/python2.7/dist-packages/flup/server/fcgi_base.py", line 1159, in handler
    result = self.application(environ, start_response)
  File "/usr/local/lib/python2.7/dist-packages/django/core/handlers/wsgi.py", line 219, in __call__
    self.load_middleware()
  File "/usr/local/lib/python2.7/dist-packages/django/core/handlers/base.py", line 47, in load_middleware
    raise exceptions.ImproperlyConfigured('Error importing middleware %s: "%s"' % (mw_module, e))
ImproperlyConfigured: Error importing middleware hopeapp.middleware.crossdomainxhr: "No module named middleware.crossdomainxhr"" while reading response header from upstream, client: 192.168.56.1, server: , request: "GET / HTTP/1.1", upstream: "fastcgi://127.0.0.1:9000", host: "in.dev"
2014/01/26 23:23:14 [error] 3632#0: *3 open() "/var/www/hope/hope/media/landing/img/containers/iphone-5.png" failed (2: No such file or directory), client: 192.168.56.1, server: , request: "GET /media/landing/img/containers/iphone-5.png HTTP/1.1", host: "in.dev", referrer: "http://in.dev/"
2014/01/26 23:37:17 [error] 3632#0: *29 open() "/var/www/hope/hope/media/landing/img/containers/iphone-5.png" failed (2: No such file or directory), client: 192.168.56.1, server: , request: "GET /media/landing/img/containers/iphone-5.png HTTP/1.1", host: "in.dev", referrer: "http://in.dev/"
2014/01/27 11:08:10 [error] 3655#0: *44 open() "/var/www/hope/hope/media/landing/img/containers/iphone-5.png" failed (2: No such file or directory), client: 192.168.56.1, server: , request: "GET /media/landing/img/containers/iphone-5.png HTTP/1.1", host: "in.dev", referrer: "http://in.dev/"
2014/01/27 15:43:24 [error] 3655#0: *464 FastCGI sent in stderr: "" while reading response header from upstream, client: 192.168.56.1, server: , request: "GET /hope/occurrences/latest/1/0 HTTP/1.1", upstream: "fastcgi://127.0.0.1:9000", host: "in.dev", referrer: "http://in.dev/"
2014/01/27 15:43:24 [error] 3655#0: *464 FastCGI sent in stderr: "Traceback (most recent call last):
  File "/usr/local/lib/python2.7/dist-packages/flup/server/fcgi_base.py", line 574, in run
    protocolStatus, appStatus = self.server.handler(self)
  File "/usr/local/lib/python2.7/dist-packages/flup/server/fcgi_base.py", line 1159, in handler
    result = self.application(environ, start_response)
  File "/usr/local/lib/python2.7/dist-packages/django/core/handlers/wsgi.py", line 241, in __call__
    response = self.get_response(request)
  File "/usr/local/lib/python2.7/dist-packages/django/core/handlers/base.py", line 178, in get_response
    signals.got_request_exception.send(sender=self.__class__, request=request)
  File "/usr/local/lib/python2.7/dist-packages/django/dispatch/dispatcher.py", line 172, in send
    response = receiver(signal=self, sender=sender, **named)
  File "/usr/local/lib/python2.7/dist-packages/django/db/__init__.py", line 62, in _rollback_on_exception
    transaction.rollback_unless_managed(using=conn)
  File "/usr/local/lib/python2.7/dist-packages/django/db/transaction.py", line 129, in rollback_unless_managed
    connection.rollback_unless_managed()
  File "/usr/local/lib/python2.7/dist-packages/django/db/backends/__init__.py", line 214, in rollback_unless_managed
    self._rollback()
  File "/usr/local/lib/python2.7/dist-packages/django/db/backends/mysql/base.py", line 404, in _rollback
    BaseDatabaseWrapper._rollback(self)
  File "/usr/local/lib/python2.7/dist-packages/django/db/backends/__init__.py", line 54, in _rollback
    return self.connection.rollback()
OperationalError: (2006, 'MySQL server has gone away')" while reading response header from upstream, client: 192.168.56.1, server: , request: "GET /hope/occurrences/latest/1/0 HTTP/1.1", upstream: "fastcgi://127.0.0.1:9000", host: "in.dev", referrer: "http://in.dev/"
2014/01/27 15:43:25 [error] 3655#0: *463 FastCGI sent in stderr: "" while reading response header from upstream, client: 192.168.56.1, server: , request: "GET /hope/occurrences/all/0 HTTP/1.1", upstream: "fastcgi://127.0.0.1:9000", host: "in.dev", referrer: "http://in.dev/"
2014/01/27 15:43:25 [error] 3655#0: *463 FastCGI sent in stderr: "Traceback (most recent call last):
  File "/usr/local/lib/python2.7/dist-packages/flup/server/fcgi_base.py", line 574, in run
    protocolStatus, appStatus = self.server.handler(self)
  File "/usr/local/lib/python2.7/dist-packages/flup/server/fcgi_base.py", line 1159, in handler
    result = self.application(environ, start_response)
  File "/usr/local/lib/python2.7/dist-packages/django/core/handlers/wsgi.py", line 241, in __call__
    response = self.get_response(request)
  File "/usr/local/lib/python2.7/dist-packages/django/core/handlers/base.py", line 178, in get_response
    signals.got_request_exception.send(sender=self.__class__, request=request)
  File "/usr/local/lib/python2.7/dist-packages/django/dispatch/dispatcher.py", line 172, in send
    response = receiver(signal=self, sender=sender, **named)
  File "/usr/local/lib/python2.7/dist-packages/django/db/__init__.py", line 62, in _rollback_on_exception
    transaction.rollback_unless_managed(using=conn)
  File "/usr/local/lib/python2.7/dist-packages/django/db/transaction.py", line 129, in rollback_unless_managed
    connection.rollback_unless_managed()
  File "/usr/local/lib/python2.7/dist-packages/django/db/backends/__init__.py", line 214, in rollback_unless_managed
    self._rollback()
  File "/usr/local/lib/python2.7/dist-packages/django/db/backends/mysql/base.py", line 404, in _rollback
    BaseDatabaseWrapper._rollback(self)
  File "/usr/local/lib/python2.7/dist-packages/django/db/backends/__init__.py", line 54, in _rollback
    return self.connection.rollback()
OperationalError: (2006, 'MySQL server has gone away')" while reading response header from upstream, client: 192.168.56.1, server: , request: "GET /hope/occurrences/all/0 HTTP/1.1", upstream: "fastcgi://127.0.0.1:9000", host: "in.dev", referrer: "http://in.dev/"
2014/01/27 17:33:42 [error] 3655#0: *559 open() "/var/www/hope/hope/media/landing/img/containers/iphone-5.png" failed (2: No such file or directory), client: 192.168.56.1, server: , request: "GET /media/landing/img/containers/iphone-5.png HTTP/1.1", host: "in.dev", referrer: "http://in.dev/"
2014/01/27 17:51:02 [error] 3655#0: *629 FastCGI sent in stderr: "" while reading response header from upstream, client: 192.168.56.1, server: , request: "GET /hope/register/ HTTP/1.1", upstream: "fastcgi://127.0.0.1:9000", host: "in.dev"
2014/01/27 17:51:02 [error] 3655#0: *629 FastCGI sent in stderr: "Traceback (most recent call last):
  File "/usr/local/lib/python2.7/dist-packages/flup/server/fcgi_base.py", line 574, in run
    protocolStatus, appStatus = self.server.handler(self)
  File "/usr/local/lib/python2.7/dist-packages/flup/server/fcgi_base.py", line 1159, in handler
    result = self.application(environ, start_response)
  File "/usr/local/lib/python2.7/dist-packages/django/core/handlers/wsgi.py", line 241, in __call__
    response = self.get_response(request)
  File "/usr/local/lib/python2.7/dist-packages/django/core/handlers/base.py", line 178, in get_response
    signals.got_request_exception.send(sender=self.__class__, request=request)
  File "/usr/local/lib/python2.7/dist-packages/django/dispatch/dispatcher.py", line 172, in send
    response = receiver(signal=self, sender=sender, **named)
  File "/usr/local/lib/python2.7/dist-packages/django/db/__init__.py", line 62, in _rollback_on_exception
    transaction.rollback_unless_managed(using=conn)
  File "/usr/local/lib/python2.7/dist-packages/django/db/transaction.py", line 129, in rollback_unless_managed
    connection.rollback_unless_managed()
  File "/usr/local/lib/python2.7/dist-packages/django/db/backends/__init__.py", line 214, in rollback_unless_managed
    self._rollback()
  File "/usr/local/lib/python2.7/dist-packages/django/db/backends/mysql/base.py", line 404, in _rollback
    BaseDatabaseWrapper._rollback(self)
  File "/usr/local/lib/python2.7/dist-packages/django/db/backends/__init__.py", line 54, in _rollback
    return self.connection.rollback()
OperationalError: (2006, 'MySQL server has gone away')" while reading response header from upstream, client: 192.168.56.1, server: , request: "GET /hope/register/ HTTP/1.1", upstream: "fastcgi://127.0.0.1:9000", host: "in.dev"
2014/01/27 18:05:23 [error] 3655#0: *659 FastCGI sent in stderr: "" while reading response header from upstream, client: 192.168.56.1, server: , request: "GET /hope/register/ HTTP/1.1", upstream: "fastcgi://127.0.0.1:9000", host: "in.dev"
2014/01/27 18:05:23 [error] 3655#0: *659 FastCGI sent in stderr: "Traceback (most recent call last):
  File "/usr/local/lib/python2.7/dist-packages/flup/server/fcgi_base.py", line 574, in run
    protocolStatus, appStatus = self.server.handler(self)
  File "/usr/local/lib/python2.7/dist-packages/flup/server/fcgi_base.py", line 1159, in handler
    result = self.application(environ, start_response)
  File "/usr/local/lib/python2.7/dist-packages/django/core/handlers/wsgi.py", line 241, in __call__
    response = self.get_response(request)
  File "/usr/local/lib/python2.7/dist-packages/django/core/handlers/base.py", line 178, in get_response
    signals.got_request_exception.send(sender=self.__class__, request=request)
  File "/usr/local/lib/python2.7/dist-packages/django/dispatch/dispatcher.py", line 172, in send
    response = receiver(signal=self, sender=sender, **named)
  File "/usr/local/lib/python2.7/dist-packages/django/db/__init__.py", line 62, in _rollback_on_exception
    transaction.rollback_unless_managed(using=conn)
  File "/usr/local/lib/python2.7/dist-packages/django/db/transaction.py", line 129, in rollback_unless_managed
    connection.rollback_unless_managed()
  File "/usr/local/lib/python2.7/dist-packages/django/db/backends/__init__.py", line 214, in rollback_unless_managed
    self._rollback()
  File "/usr/local/lib/python2.7/dist-packages/django/db/backends/mysql/base.py", line 404, in _rollback
    BaseDatabaseWrapper._rollback(self)
  File "/usr/local/lib/python2.7/dist-packages/django/db/backends/__init__.py", line 54, in _rollback
    return self.connection.rollback()
OperationalError: (2006, 'MySQL server has gone away')" while reading response header from upstream, client: 192.168.56.1, server: , request: "GET /hope/register/ HTTP/1.1", upstream: "fastcgi://127.0.0.1:9000", host: "in.dev"
2014/01/27 18:10:28 [error] 3655#0: *693 open() "/var/www/hope/hope/media/landing/img/containers/iphone-5.png" failed (2: No such file or directory), client: 192.168.56.1, server: , request: "GET /media/landing/img/containers/iphone-5.png HTTP/1.1", host: "in.dev", referrer: "http://in.dev/"
2014/01/27 18:19:24 [error] 3655#0: *708 open() "/var/www/hope/hope/media/landing/img/containers/iphone-5.png" failed (2: No such file or directory), client: 192.168.56.1, server: , request: "GET /media/landing/img/containers/iphone-5.png HTTP/1.1", host: "in.dev", referrer: "http://in.dev/"
2014/01/27 18:20:28 [error] 3655#0: *716 open() "/var/www/hope/hope/media/landing/img/containers/iphone-5.png" failed (2: No such file or directory), client: 192.168.56.1, server: , request: "GET /media/landing/img/containers/iphone-5.png HTTP/1.1", host: "in.dev", referrer: "http://in.dev/"
2014/01/27 18:20:28 [error] 3655#0: *722 open() "/var/www/hope/hope/media/landing/img/containers/iphone-5.png" failed (2: No such file or directory), client: 192.168.56.1, server: , request: "GET /media/landing/img/containers/iphone-5.png HTTP/1.1", host: "in.dev", referrer: "http://in.dev/"
2014/01/27 18:28:35 [error] 3655#0: *758 open() "/var/www/hope/hope/media/landing/img/containers/iphone-5.png" failed (2: No such file or directory), client: 192.168.56.1, server: , request: "GET /media/landing/img/containers/iphone-5.png HTTP/1.1", host: "in.dev", referrer: "http://in.dev/"
2014/01/27 18:29:07 [error] 3655#0: *758 open() "/var/www/hope/hope/media/landing/img/containers/iphone-5.png" failed (2: No such file or directory), client: 192.168.56.1, server: , request: "GET /media/landing/img/containers/iphone-5.png HTTP/1.1", host: "in.dev", referrer: "http://in.dev/"
2014/01/27 19:38:31 [error] 3655#0: *780 open() "/var/www/hope/hope/media/landing/img/containers/iphone-5.png" failed (2: No such file or directory), client: 192.168.56.1, server: , request: "GET /media/landing/img/containers/iphone-5.png HTTP/1.1", host: "in.dev", referrer: "http://in.dev/"
2014/01/28 00:05:03 [error] 3655#0: *782 open() "/var/www/hope/hope/media/landing/img/containers/iphone-5.png" failed (2: No such file or directory), client: 192.168.56.1, server: , request: "GET /media/landing/img/containers/iphone-5.png HTTP/1.1", host: "in.dev", referrer: "http://in.dev/"
2014/01/28 01:03:36 [error] 3655#0: *849 open() "/var/www/hope/hope/media/landing/img/containers/iphone-5.png" failed (2: No such file or directory), client: 192.168.56.1, server: , request: "GET /media/landing/img/containers/iphone-5.png HTTP/1.1", host: "in.dev", referrer: "http://in.dev/"
2014/01/31 00:53:08 [error] 3655#0: *1081 FastCGI sent in stderr: "" while reading response header from upstream, client: 192.168.56.1, server: , request: "GET /hope/occurrences/616/ HTTP/1.1", upstream: "fastcgi://127.0.0.1:9000", host: "in.dev", referrer: "http://in.dev/"
2014/01/31 00:53:08 [error] 3655#0: *1081 FastCGI sent in stderr: "Traceback (most recent call last):
  File "/usr/local/lib/python2.7/dist-packages/flup/server/fcgi_base.py", line 574, in run
    protocolStatus, appStatus = self.server.handler(self)
  File "/usr/local/lib/python2.7/dist-packages/flup/server/fcgi_base.py", line 1159, in handler
    result = self.application(environ, start_response)
  File "/usr/local/lib/python2.7/dist-packages/django/core/handlers/wsgi.py", line 241, in __call__
    response = self.get_response(request)
  File "/usr/local/lib/python2.7/dist-packages/django/core/handlers/base.py", line 178, in get_response
    signals.got_request_exception.send(sender=self.__class__, request=request)
  File "/usr/local/lib/python2.7/dist-packages/django/dispatch/dispatcher.py", line 172, in send
    response = receiver(signal=self, sender=sender, **named)
  File "/usr/local/lib/python2.7/dist-packages/django/db/__init__.py", line 62, in _rollback_on_exception
    transaction.rollback_unless_managed(using=conn)
  File "/usr/local/lib/python2.7/dist-packages/django/db/transaction.py", line 129, in rollback_unless_managed
    connection.rollback_unless_managed()
  File "/usr/local/lib/python2.7/dist-packages/django/db/backends/__init__.py", line 214, in rollback_unless_managed
    self._rollback()
  File "/usr/local/lib/python2.7/dist-packages/django/db/backends/mysql/base.py", line 404, in _rollback
    BaseDatabaseWrapper._rollback(self)
  File "/usr/local/lib/python2.7/dist-packages/django/db/backends/__init__.py", line 54, in _rollback
    return self.connection.rollback()
OperationalError: (2006, 'MySQL server has gone away')" while reading response header from upstream, client: 192.168.56.1, server: , request: "GET /hope/occurrences/616/ HTTP/1.1", upstream: "fastcgi://127.0.0.1:9000", host: "in.dev", referrer: "http://in.dev/"
2014/01/31 13:58:41 [error] 3655#0: *1487 FastCGI sent in stderr: "" while reading response header from upstream, client: 192.168.56.1, server: , request: "GET /hope/occurrences/290/ HTTP/1.1", upstream: "fastcgi://127.0.0.1:9000", host: "in.dev"
2014/01/31 13:58:41 [error] 3655#0: *1487 FastCGI sent in stderr: "Traceback (most recent call last):
  File "/usr/local/lib/python2.7/dist-packages/flup/server/fcgi_base.py", line 574, in run
    protocolStatus, appStatus = self.server.handler(self)
  File "/usr/local/lib/python2.7/dist-packages/flup/server/fcgi_base.py", line 1159, in handler
    result = self.application(environ, start_response)
  File "/usr/local/lib/python2.7/dist-packages/django/core/handlers/wsgi.py", line 241, in __call__
    response = self.get_response(request)
  File "/usr/local/lib/python2.7/dist-packages/django/core/handlers/base.py", line 178, in get_response
    signals.got_request_exception.send(sender=self.__class__, request=request)
  File "/usr/local/lib/python2.7/dist-packages/django/dispatch/dispatcher.py", line 172, in send
    response = receiver(signal=self, sender=sender, **named)
  File "/usr/local/lib/python2.7/dist-packages/django/db/__init__.py", line 62, in _rollback_on_exception
    transaction.rollback_unless_managed(using=conn)
  File "/usr/local/lib/python2.7/dist-packages/django/db/transaction.py", line 129, in rollback_unless_managed
    connection.rollback_unless_managed()
  File "/usr/local/lib/python2.7/dist-packages/django/db/backends/__init__.py", line 214, in rollback_unless_managed
    self._rollback()
  File "/usr/local/lib/python2.7/dist-packages/django/db/backends/mysql/base.py", line 404, in _rollback
    BaseDatabaseWrapper._rollback(self)
  File "/usr/local/lib/python2.7/dist-packages/django/db/backends/__init__.py", line 54, in _rollback
    return self.connection.rollback()
OperationalError: (2006, 'MySQL server has gone away')" while reading response header from upstream, client: 192.168.56.1, server: , request: "GET /hope/occurrences/290/ HTTP/1.1", upstream: "fastcgi://127.0.0.1:9000", host: "in.dev"
2014/01/31 13:59:03 [error] 3655#0: *1494 FastCGI sent in stderr: "" while reading response header from upstream, client: 192.168.56.1, server: , request: "GET /hope/occurrences/290/ HTTP/1.1", upstream: "fastcgi://127.0.0.1:9000", host: "in.dev"
2014/01/31 13:59:03 [error] 3655#0: *1494 FastCGI sent in stderr: "Traceback (most recent call last):
  File "/usr/local/lib/python2.7/dist-packages/flup/server/fcgi_base.py", line 574, in run
    protocolStatus, appStatus = self.server.handler(self)
  File "/usr/local/lib/python2.7/dist-packages/flup/server/fcgi_base.py", line 1159, in handler
    result = self.application(environ, start_response)
  File "/usr/local/lib/python2.7/dist-packages/django/core/handlers/wsgi.py", line 241, in __call__
    response = self.get_response(request)
  File "/usr/local/lib/python2.7/dist-packages/django/core/handlers/base.py", line 178, in get_response
    signals.got_request_exception.send(sender=self.__class__, request=request)
  File "/usr/local/lib/python2.7/dist-packages/django/dispatch/dispatcher.py", line 172, in send
    response = receiver(signal=self, sender=sender, **named)
  File "/usr/local/lib/python2.7/dist-packages/django/db/__init__.py", line 62, in _rollback_on_exception
    transaction.rollback_unless_managed(using=conn)
  File "/usr/local/lib/python2.7/dist-packages/django/db/transaction.py", line 129, in rollback_unless_managed
    connection.rollback_unless_managed()
  File "/usr/local/lib/python2.7/dist-packages/django/db/backends/__init__.py", line 214, in rollback_unless_managed
    self._rollback()
  File "/usr/local/lib/python2.7/dist-packages/django/db/backends/mysql/base.py", line 404, in _rollback
    BaseDatabaseWrapper._rollback(self)
  File "/usr/local/lib/python2.7/dist-packages/django/db/backends/__init__.py", line 54, in _rollback
    return self.connection.rollback()
OperationalError: (2006, 'MySQL server has gone away')" while reading response header from upstream, client: 192.168.56.1, server: , request: "GET /hope/occurrences/290/ HTTP/1.1", upstream: "fastcgi://127.0.0.1:9000", host: "in.dev"
2014/01/31 14:01:48 [error] 3655#0: *1502 FastCGI sent in stderr: "" while reading response header from upstream, client: 192.168.56.1, server: , request: "GET /denied/?next=/hope/occurrences/290/ HTTP/1.1", upstream: "fastcgi://127.0.0.1:9000", host: "in.dev"
2014/01/31 14:01:48 [error] 3655#0: *1502 FastCGI sent in stderr: "Traceback (most recent call last):
  File "/usr/local/lib/python2.7/dist-packages/flup/server/fcgi_base.py", line 574, in run
    protocolStatus, appStatus = self.server.handler(self)
  File "/usr/local/lib/python2.7/dist-packages/flup/server/fcgi_base.py", line 1159, in handler
    result = self.application(environ, start_response)
  File "/usr/local/lib/python2.7/dist-packages/django/core/handlers/wsgi.py", line 241, in __call__
    response = self.get_response(request)
  File "/usr/local/lib/python2.7/dist-packages/django/core/handlers/base.py", line 178, in get_response
    signals.got_request_exception.send(sender=self.__class__, request=request)
  File "/usr/local/lib/python2.7/dist-packages/django/dispatch/dispatcher.py", line 172, in send
    response = receiver(signal=self, sender=sender, **named)
  File "/usr/local/lib/python2.7/dist-packages/django/db/__init__.py", line 62, in _rollback_on_exception
    transaction.rollback_unless_managed(using=conn)
  File "/usr/local/lib/python2.7/dist-packages/django/db/transaction.py", line 129, in rollback_unless_managed
    connection.rollback_unless_managed()
  File "/usr/local/lib/python2.7/dist-packages/django/db/backends/__init__.py", line 214, in rollback_unless_managed
    self._rollback()
  File "/usr/local/lib/python2.7/dist-packages/django/db/backends/mysql/base.py", line 404, in _rollback
    BaseDatabaseWrapper._rollback(self)
  File "/usr/local/lib/python2.7/dist-packages/django/db/backends/__init__.py", line 54, in _rollback
    return self.connection.rollback()
OperationalError: (2006, 'MySQL server has gone away')" while reading response header from upstream, client: 192.168.56.1, server: , request: "GET /denied/?next=/hope/occurrences/290/ HTTP/1.1", upstream: "fastcgi://127.0.0.1:9000", host: "in.dev"
